Internal Server Error: /api/quality/register_quality/
Traceback (most recent call last):
  File "C:\Users\Davide\Documents\Proyectos Python\aquanode\env\lib\site-packages\django\core\handlers\exception.py", line 55, in inner
    response = get_response(request)
  File "C:\Users\Davide\Documents\Proyectos Python\aquanode\env\lib\site-packages\django\core\handlers\base.py", line 197, in _get_response
    response = wrapped_callback(request, *callback_args, **callback_kwargs)
  File "C:\Users\Davide\Documents\Proyectos Python\aquanode\env\lib\site-packages\django\views\decorators\csrf.py", line 54, in wrapped_view
    return view_func(*args, **kwargs)
  File "C:\Users\Davide\Documents\Proyectos Python\aquanode\env\lib\site-packages\django\views\generic\base.py", line 103, in view
    return self.dispatch(request, *args, **kwargs)
  File "C:\Users\Davide\Documents\Proyectos Python\aquanode\env\lib\site-packages\rest_framework\views.py", line 509, in dispatch
    response = self.handle_exception(exc)
  File "C:\Users\Davide\Documents\Proyectos Python\aquanode\env\lib\site-packages\rest_framework\views.py", line 469, in handle_exception
    self.raise_uncaught_exception(exc)
  File "C:\Users\Davide\Documents\Proyectos Python\aquanode\env\lib\site-packages\rest_framework\views.py", line 480, in raise_uncaught_exception
    raise exc
  File "C:\Users\Davide\Documents\Proyectos Python\aquanode\env\lib\site-packages\rest_framework\views.py", line 506, in dispatch
    response = handler(request, *args, **kwargs)
  File "C:\Users\Davide\Documents\Proyectos Python\aquanode\env\lib\site-packages\rest_framework\decorators.py", line 50, in handler
    return func(*args, **kwargs)
  File "C:\Users\Davide\Documents\Proyectos Python\aquanode\aquanode\core\quality\views.py", line 25, in register_quality
    'ubication': data['ubicación'],
TypeError: list indices must be integers or slices, not str
"POST /api/quality/register_quality/ HTTP/1.1" 500 107704
Internal Server Error: /api/quality/register_quality/
Traceback (most recent call last):
  File "C:\Users\Davide\Documents\Proyectos Python\aquanode\env\lib\site-packages\django\core\handlers\exception.py", line 55, in inner
    response = get_response(request)
  File "C:\Users\Davide\Documents\Proyectos Python\aquanode\env\lib\site-packages\django\core\handlers\base.py", line 197, in _get_response
    response = wrapped_callback(request, *callback_args, **callback_kwargs)
  File "C:\Users\Davide\Documents\Proyectos Python\aquanode\env\lib\site-packages\django\views\decorators\csrf.py", line 54, in wrapped_view
    return view_func(*args, **kwargs)
  File "C:\Users\Davide\Documents\Proyectos Python\aquanode\env\lib\site-packages\django\views\generic\base.py", line 103, in view
    return self.dispatch(request, *args, **kwargs)
  File "C:\Users\Davide\Documents\Proyectos Python\aquanode\env\lib\site-packages\rest_framework\views.py", line 509, in dispatch
    response = self.handle_exception(exc)
  File "C:\Users\Davide\Documents\Proyectos Python\aquanode\env\lib\site-packages\rest_framework\views.py", line 469, in handle_exception
    self.raise_uncaught_exception(exc)
  File "C:\Users\Davide\Documents\Proyectos Python\aquanode\env\lib\site-packages\rest_framework\views.py", line 480, in raise_uncaught_exception
    raise exc
  File "C:\Users\Davide\Documents\Proyectos Python\aquanode\env\lib\site-packages\rest_framework\views.py", line 506, in dispatch
    response = handler(request, *args, **kwargs)
  File "C:\Users\Davide\Documents\Proyectos Python\aquanode\env\lib\site-packages\rest_framework\decorators.py", line 50, in handler
    return func(*args, **kwargs)
  File "C:\Users\Davide\Documents\Proyectos Python\aquanode\aquanode\core\quality\views.py", line 26, in register_quality
    'ubication': data['ubicación'],
TypeError: list indices must be integers or slices, not str
"POST /api/quality/register_quality/ HTTP/1.1" 500 107704
Internal Server Error: /api/quality/register_quality/
"POST /api/quality/register_quality/ HTTP/1.1" 500 93
Internal Server Error: /api/quality/register_quality/
"POST /api/quality/register_quality/ HTTP/1.1" 500 159
Internal Server Error: /api/quality/register_quality/
"POST /api/quality/register_quality/ HTTP/1.1" 500 159
Internal Server Error: /api/quality/register_quality/
"POST /api/quality/register_quality/ HTTP/1.1" 500 159
Internal Server Error: /api/diagnosis/register_diagnosis/
"POST /api/diagnosis/register_diagnosis/ HTTP/1.1" 500 110
Internal Server Error: /api/diagnosis/register_diagnosis/
"POST /api/diagnosis/register_diagnosis/ HTTP/1.1" 500 110
Internal Server Error: /api/diagnosis/register_diagnosis/
"POST /api/diagnosis/register_diagnosis/ HTTP/1.1" 500 82
Internal Server Error: /api/diagnosis/register_diagnosis/
"POST /api/diagnosis/register_diagnosis/ HTTP/1.1" 500 82
Internal Server Error: /api/users/list/
Traceback (most recent call last):
  File "C:\Users\Davide\Documents\Proyectos Python\aquanode\env\lib\site-packages\django\db\backends\base\base.py", line 282, in ensure_connection
    self.connect()
  File "C:\Users\Davide\Documents\Proyectos Python\aquanode\env\lib\site-packages\django\utils\asyncio.py", line 26, in inner
    return func(*args, **kwargs)
  File "C:\Users\Davide\Documents\Proyectos Python\aquanode\env\lib\site-packages\django\db\backends\base\base.py", line 263, in connect
    self.connection = self.get_new_connection(conn_params)
  File "C:\Users\Davide\Documents\Proyectos Python\aquanode\env\lib\site-packages\django\utils\asyncio.py", line 26, in inner
    return func(*args, **kwargs)
  File "C:\Users\Davide\Documents\Proyectos Python\aquanode\env\lib\site-packages\django\db\backends\postgresql\base.py", line 215, in get_new_connection
    connection = Database.connect(**conn_params)
  File "C:\Users\Davide\Documents\Proyectos Python\aquanode\env\lib\site-packages\psycopg2\__init__.py", line 122, in connect
    conn = _connect(dsn, connection_factory=connection_factory, **kwasync)
psycopg2.OperationalError: could not translate host name "aquadb.cngcu6yaowyr.us-east-2.rds.amazonaws.com" to address: Host desconocido. 


The above exception was the direct cause of the following exception:

Traceback (most recent call last):
  File "C:\Users\Davide\Documents\Proyectos Python\aquanode\env\lib\site-packages\django\core\handlers\exception.py", line 55, in inner
    response = get_response(request)
  File "C:\Users\Davide\Documents\Proyectos Python\aquanode\env\lib\site-packages\django\core\handlers\base.py", line 197, in _get_response
    response = wrapped_callback(request, *callback_args, **callback_kwargs)
  File "C:\Users\Davide\Documents\Proyectos Python\aquanode\env\lib\site-packages\django\views\decorators\csrf.py", line 54, in wrapped_view
    return view_func(*args, **kwargs)
  File "C:\Users\Davide\Documents\Proyectos Python\aquanode\env\lib\site-packages\django\views\generic\base.py", line 103, in view
    return self.dispatch(request, *args, **kwargs)
  File "C:\Users\Davide\Documents\Proyectos Python\aquanode\env\lib\site-packages\rest_framework\views.py", line 509, in dispatch
    response = self.handle_exception(exc)
  File "C:\Users\Davide\Documents\Proyectos Python\aquanode\env\lib\site-packages\rest_framework\views.py", line 469, in handle_exception
    self.raise_uncaught_exception(exc)
  File "C:\Users\Davide\Documents\Proyectos Python\aquanode\env\lib\site-packages\rest_framework\views.py", line 480, in raise_uncaught_exception
    raise exc
  File "C:\Users\Davide\Documents\Proyectos Python\aquanode\env\lib\site-packages\rest_framework\views.py", line 497, in dispatch
    self.initial(request, *args, **kwargs)
  File "C:\Users\Davide\Documents\Proyectos Python\aquanode\env\lib\site-packages\rest_framework\views.py", line 414, in initial
    self.perform_authentication(request)
  File "C:\Users\Davide\Documents\Proyectos Python\aquanode\env\lib\site-packages\rest_framework\views.py", line 324, in perform_authentication
    request.user
  File "C:\Users\Davide\Documents\Proyectos Python\aquanode\env\lib\site-packages\rest_framework\request.py", line 231, in user
    self._authenticate()
  File "C:\Users\Davide\Documents\Proyectos Python\aquanode\env\lib\site-packages\rest_framework\request.py", line 384, in _authenticate
    user_auth_tuple = authenticator.authenticate(self)
  File "C:\Users\Davide\Documents\Proyectos Python\aquanode\env\lib\site-packages\rest_framework_simplejwt\authentication.py", line 51, in authenticate
    return self.get_user(validated_token), validated_token
  File "C:\Users\Davide\Documents\Proyectos Python\aquanode\env\lib\site-packages\rest_framework_simplejwt\authentication.py", line 130, in get_user
    user = self.user_model.objects.get(**{api_settings.USER_ID_FIELD: user_id})
  File "C:\Users\Davide\Documents\Proyectos Python\aquanode\env\lib\site-packages\django\db\models\manager.py", line 85, in manager_method
    return getattr(self.get_queryset(), name)(*args, **kwargs)
  File "C:\Users\Davide\Documents\Proyectos Python\aquanode\env\lib\site-packages\django\db\models\query.py", line 646, in get
    num = len(clone)
  File "C:\Users\Davide\Documents\Proyectos Python\aquanode\env\lib\site-packages\django\db\models\query.py", line 376, in __len__
    self._fetch_all()
  File "C:\Users\Davide\Documents\Proyectos Python\aquanode\env\lib\site-packages\django\db\models\query.py", line 1866, in _fetch_all
    self._result_cache = list(self._iterable_class(self))
  File "C:\Users\Davide\Documents\Proyectos Python\aquanode\env\lib\site-packages\django\db\models\query.py", line 87, in __iter__
    results = compiler.execute_sql(
  File "C:\Users\Davide\Documents\Proyectos Python\aquanode\env\lib\site-packages\django\db\models\sql\compiler.py", line 1393, in execute_sql
    cursor = self.connection.cursor()
  File "C:\Users\Davide\Documents\Proyectos Python\aquanode\env\lib\site-packages\django\utils\asyncio.py", line 26, in inner
    return func(*args, **kwargs)
  File "C:\Users\Davide\Documents\Proyectos Python\aquanode\env\lib\site-packages\django\db\backends\base\base.py", line 323, in cursor
    return self._cursor()
  File "C:\Users\Davide\Documents\Proyectos Python\aquanode\env\lib\site-packages\django\db\backends\base\base.py", line 299, in _cursor
    self.ensure_connection()
  File "C:\Users\Davide\Documents\Proyectos Python\aquanode\env\lib\site-packages\django\utils\asyncio.py", line 26, in inner
    return func(*args, **kwargs)
  File "C:\Users\Davide\Documents\Proyectos Python\aquanode\env\lib\site-packages\django\db\backends\base\base.py", line 281, in ensure_connection
    with self.wrap_database_errors:
  File "C:\Users\Davide\Documents\Proyectos Python\aquanode\env\lib\site-packages\django\db\utils.py", line 91, in __exit__
    raise dj_exc_value.with_traceback(traceback) from exc_value
  File "C:\Users\Davide\Documents\Proyectos Python\aquanode\env\lib\site-packages\django\db\backends\base\base.py", line 282, in ensure_connection
    self.connect()
  File "C:\Users\Davide\Documents\Proyectos Python\aquanode\env\lib\site-packages\django\utils\asyncio.py", line 26, in inner
    return func(*args, **kwargs)
  File "C:\Users\Davide\Documents\Proyectos Python\aquanode\env\lib\site-packages\django\db\backends\base\base.py", line 263, in connect
    self.connection = self.get_new_connection(conn_params)
  File "C:\Users\Davide\Documents\Proyectos Python\aquanode\env\lib\site-packages\django\utils\asyncio.py", line 26, in inner
    return func(*args, **kwargs)
  File "C:\Users\Davide\Documents\Proyectos Python\aquanode\env\lib\site-packages\django\db\backends\postgresql\base.py", line 215, in get_new_connection
    connection = Database.connect(**conn_params)
  File "C:\Users\Davide\Documents\Proyectos Python\aquanode\env\lib\site-packages\psycopg2\__init__.py", line 122, in connect
    conn = _connect(dsn, connection_factory=connection_factory, **kwasync)
django.db.utils.OperationalError: could not translate host name "aquadb.cngcu6yaowyr.us-east-2.rds.amazonaws.com" to address: Host desconocido. 

"GET /api/users/list/ HTTP/1.1" 500 221670
Internal Server Error: /api/users/list/
Traceback (most recent call last):
  File "C:\Users\Davide\Documents\Proyectos Python\aquanode\env\lib\site-packages\django\db\backends\base\base.py", line 282, in ensure_connection
    self.connect()
  File "C:\Users\Davide\Documents\Proyectos Python\aquanode\env\lib\site-packages\django\utils\asyncio.py", line 26, in inner
    return func(*args, **kwargs)
  File "C:\Users\Davide\Documents\Proyectos Python\aquanode\env\lib\site-packages\django\db\backends\base\base.py", line 263, in connect
    self.connection = self.get_new_connection(conn_params)
  File "C:\Users\Davide\Documents\Proyectos Python\aquanode\env\lib\site-packages\django\utils\asyncio.py", line 26, in inner
    return func(*args, **kwargs)
  File "C:\Users\Davide\Documents\Proyectos Python\aquanode\env\lib\site-packages\django\db\backends\postgresql\base.py", line 215, in get_new_connection
    connection = Database.connect(**conn_params)
  File "C:\Users\Davide\Documents\Proyectos Python\aquanode\env\lib\site-packages\psycopg2\__init__.py", line 122, in connect
    conn = _connect(dsn, connection_factory=connection_factory, **kwasync)
psycopg2.OperationalError: could not translate host name "aquadb.cngcu6yaowyr.us-east-2.rds.amazonaws.com" to address: Host desconocido. 


The above exception was the direct cause of the following exception:

Traceback (most recent call last):
  File "C:\Users\Davide\Documents\Proyectos Python\aquanode\env\lib\site-packages\django\core\handlers\exception.py", line 55, in inner
    response = get_response(request)
  File "C:\Users\Davide\Documents\Proyectos Python\aquanode\env\lib\site-packages\django\core\handlers\base.py", line 197, in _get_response
    response = wrapped_callback(request, *callback_args, **callback_kwargs)
  File "C:\Users\Davide\Documents\Proyectos Python\aquanode\env\lib\site-packages\django\views\decorators\csrf.py", line 54, in wrapped_view
    return view_func(*args, **kwargs)
  File "C:\Users\Davide\Documents\Proyectos Python\aquanode\env\lib\site-packages\django\views\generic\base.py", line 103, in view
    return self.dispatch(request, *args, **kwargs)
  File "C:\Users\Davide\Documents\Proyectos Python\aquanode\env\lib\site-packages\rest_framework\views.py", line 509, in dispatch
    response = self.handle_exception(exc)
  File "C:\Users\Davide\Documents\Proyectos Python\aquanode\env\lib\site-packages\rest_framework\views.py", line 469, in handle_exception
    self.raise_uncaught_exception(exc)
  File "C:\Users\Davide\Documents\Proyectos Python\aquanode\env\lib\site-packages\rest_framework\views.py", line 480, in raise_uncaught_exception
    raise exc
  File "C:\Users\Davide\Documents\Proyectos Python\aquanode\env\lib\site-packages\rest_framework\views.py", line 497, in dispatch
    self.initial(request, *args, **kwargs)
  File "C:\Users\Davide\Documents\Proyectos Python\aquanode\env\lib\site-packages\rest_framework\views.py", line 414, in initial
    self.perform_authentication(request)
  File "C:\Users\Davide\Documents\Proyectos Python\aquanode\env\lib\site-packages\rest_framework\views.py", line 324, in perform_authentication
    request.user
  File "C:\Users\Davide\Documents\Proyectos Python\aquanode\env\lib\site-packages\rest_framework\request.py", line 231, in user
    self._authenticate()
  File "C:\Users\Davide\Documents\Proyectos Python\aquanode\env\lib\site-packages\rest_framework\request.py", line 384, in _authenticate
    user_auth_tuple = authenticator.authenticate(self)
  File "C:\Users\Davide\Documents\Proyectos Python\aquanode\env\lib\site-packages\rest_framework_simplejwt\authentication.py", line 51, in authenticate
    return self.get_user(validated_token), validated_token
  File "C:\Users\Davide\Documents\Proyectos Python\aquanode\env\lib\site-packages\rest_framework_simplejwt\authentication.py", line 130, in get_user
    user = self.user_model.objects.get(**{api_settings.USER_ID_FIELD: user_id})
  File "C:\Users\Davide\Documents\Proyectos Python\aquanode\env\lib\site-packages\django\db\models\manager.py", line 85, in manager_method
    return getattr(self.get_queryset(), name)(*args, **kwargs)
  File "C:\Users\Davide\Documents\Proyectos Python\aquanode\env\lib\site-packages\django\db\models\query.py", line 646, in get
    num = len(clone)
  File "C:\Users\Davide\Documents\Proyectos Python\aquanode\env\lib\site-packages\django\db\models\query.py", line 376, in __len__
    self._fetch_all()
  File "C:\Users\Davide\Documents\Proyectos Python\aquanode\env\lib\site-packages\django\db\models\query.py", line 1866, in _fetch_all
    self._result_cache = list(self._iterable_class(self))
  File "C:\Users\Davide\Documents\Proyectos Python\aquanode\env\lib\site-packages\django\db\models\query.py", line 87, in __iter__
    results = compiler.execute_sql(
  File "C:\Users\Davide\Documents\Proyectos Python\aquanode\env\lib\site-packages\django\db\models\sql\compiler.py", line 1393, in execute_sql
    cursor = self.connection.cursor()
  File "C:\Users\Davide\Documents\Proyectos Python\aquanode\env\lib\site-packages\django\utils\asyncio.py", line 26, in inner
    return func(*args, **kwargs)
  File "C:\Users\Davide\Documents\Proyectos Python\aquanode\env\lib\site-packages\django\db\backends\base\base.py", line 323, in cursor
    return self._cursor()
  File "C:\Users\Davide\Documents\Proyectos Python\aquanode\env\lib\site-packages\django\db\backends\base\base.py", line 299, in _cursor
    self.ensure_connection()
  File "C:\Users\Davide\Documents\Proyectos Python\aquanode\env\lib\site-packages\django\utils\asyncio.py", line 26, in inner
    return func(*args, **kwargs)
  File "C:\Users\Davide\Documents\Proyectos Python\aquanode\env\lib\site-packages\django\db\backends\base\base.py", line 281, in ensure_connection
    with self.wrap_database_errors:
  File "C:\Users\Davide\Documents\Proyectos Python\aquanode\env\lib\site-packages\django\db\utils.py", line 91, in __exit__
    raise dj_exc_value.with_traceback(traceback) from exc_value
  File "C:\Users\Davide\Documents\Proyectos Python\aquanode\env\lib\site-packages\django\db\backends\base\base.py", line 282, in ensure_connection
    self.connect()
  File "C:\Users\Davide\Documents\Proyectos Python\aquanode\env\lib\site-packages\django\utils\asyncio.py", line 26, in inner
    return func(*args, **kwargs)
  File "C:\Users\Davide\Documents\Proyectos Python\aquanode\env\lib\site-packages\django\db\backends\base\base.py", line 263, in connect
    self.connection = self.get_new_connection(conn_params)
  File "C:\Users\Davide\Documents\Proyectos Python\aquanode\env\lib\site-packages\django\utils\asyncio.py", line 26, in inner
    return func(*args, **kwargs)
  File "C:\Users\Davide\Documents\Proyectos Python\aquanode\env\lib\site-packages\django\db\backends\postgresql\base.py", line 215, in get_new_connection
    connection = Database.connect(**conn_params)
  File "C:\Users\Davide\Documents\Proyectos Python\aquanode\env\lib\site-packages\psycopg2\__init__.py", line 122, in connect
    conn = _connect(dsn, connection_factory=connection_factory, **kwasync)
django.db.utils.OperationalError: could not translate host name "aquadb.cngcu6yaowyr.us-east-2.rds.amazonaws.com" to address: Host desconocido. 

"GET /api/users/list/ HTTP/1.1" 500 221670
Internal Server Error: /api/users/list/
Traceback (most recent call last):
  File "C:\Users\Davide\Documents\Proyectos Python\aquanode\env\lib\site-packages\django\db\backends\base\base.py", line 282, in ensure_connection
    self.connect()
  File "C:\Users\Davide\Documents\Proyectos Python\aquanode\env\lib\site-packages\django\utils\asyncio.py", line 26, in inner
    return func(*args, **kwargs)
  File "C:\Users\Davide\Documents\Proyectos Python\aquanode\env\lib\site-packages\django\db\backends\base\base.py", line 263, in connect
    self.connection = self.get_new_connection(conn_params)
  File "C:\Users\Davide\Documents\Proyectos Python\aquanode\env\lib\site-packages\django\utils\asyncio.py", line 26, in inner
    return func(*args, **kwargs)
  File "C:\Users\Davide\Documents\Proyectos Python\aquanode\env\lib\site-packages\django\db\backends\postgresql\base.py", line 215, in get_new_connection
    connection = Database.connect(**conn_params)
  File "C:\Users\Davide\Documents\Proyectos Python\aquanode\env\lib\site-packages\psycopg2\__init__.py", line 122, in connect
    conn = _connect(dsn, connection_factory=connection_factory, **kwasync)
psycopg2.OperationalError: could not translate host name "aquadb.cngcu6yaowyr.us-east-2.rds.amazonaws.com" to address: Host desconocido. 


The above exception was the direct cause of the following exception:

Traceback (most recent call last):
  File "C:\Users\Davide\Documents\Proyectos Python\aquanode\env\lib\site-packages\django\core\handlers\exception.py", line 55, in inner
    response = get_response(request)
  File "C:\Users\Davide\Documents\Proyectos Python\aquanode\env\lib\site-packages\django\core\handlers\base.py", line 197, in _get_response
    response = wrapped_callback(request, *callback_args, **callback_kwargs)
  File "C:\Users\Davide\Documents\Proyectos Python\aquanode\env\lib\site-packages\django\views\decorators\csrf.py", line 54, in wrapped_view
    return view_func(*args, **kwargs)
  File "C:\Users\Davide\Documents\Proyectos Python\aquanode\env\lib\site-packages\django\views\generic\base.py", line 103, in view
    return self.dispatch(request, *args, **kwargs)
  File "C:\Users\Davide\Documents\Proyectos Python\aquanode\env\lib\site-packages\rest_framework\views.py", line 509, in dispatch
    response = self.handle_exception(exc)
  File "C:\Users\Davide\Documents\Proyectos Python\aquanode\env\lib\site-packages\rest_framework\views.py", line 469, in handle_exception
    self.raise_uncaught_exception(exc)
  File "C:\Users\Davide\Documents\Proyectos Python\aquanode\env\lib\site-packages\rest_framework\views.py", line 480, in raise_uncaught_exception
    raise exc
  File "C:\Users\Davide\Documents\Proyectos Python\aquanode\env\lib\site-packages\rest_framework\views.py", line 497, in dispatch
    self.initial(request, *args, **kwargs)
  File "C:\Users\Davide\Documents\Proyectos Python\aquanode\env\lib\site-packages\rest_framework\views.py", line 414, in initial
    self.perform_authentication(request)
  File "C:\Users\Davide\Documents\Proyectos Python\aquanode\env\lib\site-packages\rest_framework\views.py", line 324, in perform_authentication
    request.user
  File "C:\Users\Davide\Documents\Proyectos Python\aquanode\env\lib\site-packages\rest_framework\request.py", line 231, in user
    self._authenticate()
  File "C:\Users\Davide\Documents\Proyectos Python\aquanode\env\lib\site-packages\rest_framework\request.py", line 384, in _authenticate
    user_auth_tuple = authenticator.authenticate(self)
  File "C:\Users\Davide\Documents\Proyectos Python\aquanode\env\lib\site-packages\rest_framework_simplejwt\authentication.py", line 51, in authenticate
    return self.get_user(validated_token), validated_token
  File "C:\Users\Davide\Documents\Proyectos Python\aquanode\env\lib\site-packages\rest_framework_simplejwt\authentication.py", line 130, in get_user
    user = self.user_model.objects.get(**{api_settings.USER_ID_FIELD: user_id})
  File "C:\Users\Davide\Documents\Proyectos Python\aquanode\env\lib\site-packages\django\db\models\manager.py", line 85, in manager_method
    return getattr(self.get_queryset(), name)(*args, **kwargs)
  File "C:\Users\Davide\Documents\Proyectos Python\aquanode\env\lib\site-packages\django\db\models\query.py", line 646, in get
    num = len(clone)
  File "C:\Users\Davide\Documents\Proyectos Python\aquanode\env\lib\site-packages\django\db\models\query.py", line 376, in __len__
    self._fetch_all()
  File "C:\Users\Davide\Documents\Proyectos Python\aquanode\env\lib\site-packages\django\db\models\query.py", line 1866, in _fetch_all
    self._result_cache = list(self._iterable_class(self))
  File "C:\Users\Davide\Documents\Proyectos Python\aquanode\env\lib\site-packages\django\db\models\query.py", line 87, in __iter__
    results = compiler.execute_sql(
  File "C:\Users\Davide\Documents\Proyectos Python\aquanode\env\lib\site-packages\django\db\models\sql\compiler.py", line 1393, in execute_sql
    cursor = self.connection.cursor()
  File "C:\Users\Davide\Documents\Proyectos Python\aquanode\env\lib\site-packages\django\utils\asyncio.py", line 26, in inner
    return func(*args, **kwargs)
  File "C:\Users\Davide\Documents\Proyectos Python\aquanode\env\lib\site-packages\django\db\backends\base\base.py", line 323, in cursor
    return self._cursor()
  File "C:\Users\Davide\Documents\Proyectos Python\aquanode\env\lib\site-packages\django\db\backends\base\base.py", line 299, in _cursor
    self.ensure_connection()
  File "C:\Users\Davide\Documents\Proyectos Python\aquanode\env\lib\site-packages\django\utils\asyncio.py", line 26, in inner
    return func(*args, **kwargs)
  File "C:\Users\Davide\Documents\Proyectos Python\aquanode\env\lib\site-packages\django\db\backends\base\base.py", line 281, in ensure_connection
    with self.wrap_database_errors:
  File "C:\Users\Davide\Documents\Proyectos Python\aquanode\env\lib\site-packages\django\db\utils.py", line 91, in __exit__
    raise dj_exc_value.with_traceback(traceback) from exc_value
  File "C:\Users\Davide\Documents\Proyectos Python\aquanode\env\lib\site-packages\django\db\backends\base\base.py", line 282, in ensure_connection
    self.connect()
  File "C:\Users\Davide\Documents\Proyectos Python\aquanode\env\lib\site-packages\django\utils\asyncio.py", line 26, in inner
    return func(*args, **kwargs)
  File "C:\Users\Davide\Documents\Proyectos Python\aquanode\env\lib\site-packages\django\db\backends\base\base.py", line 263, in connect
    self.connection = self.get_new_connection(conn_params)
  File "C:\Users\Davide\Documents\Proyectos Python\aquanode\env\lib\site-packages\django\utils\asyncio.py", line 26, in inner
    return func(*args, **kwargs)
  File "C:\Users\Davide\Documents\Proyectos Python\aquanode\env\lib\site-packages\django\db\backends\postgresql\base.py", line 215, in get_new_connection
    connection = Database.connect(**conn_params)
  File "C:\Users\Davide\Documents\Proyectos Python\aquanode\env\lib\site-packages\psycopg2\__init__.py", line 122, in connect
    conn = _connect(dsn, connection_factory=connection_factory, **kwasync)
django.db.utils.OperationalError: could not translate host name "aquadb.cngcu6yaowyr.us-east-2.rds.amazonaws.com" to address: Host desconocido. 

"GET /api/users/list/ HTTP/1.1" 500 221670
Internal Server Error: /api/users/list/
Traceback (most recent call last):
  File "C:\Users\Davide\Documents\Proyectos Python\aquanode\env\lib\site-packages\django\db\backends\base\base.py", line 282, in ensure_connection
    self.connect()
  File "C:\Users\Davide\Documents\Proyectos Python\aquanode\env\lib\site-packages\django\utils\asyncio.py", line 26, in inner
    return func(*args, **kwargs)
  File "C:\Users\Davide\Documents\Proyectos Python\aquanode\env\lib\site-packages\django\db\backends\base\base.py", line 263, in connect
    self.connection = self.get_new_connection(conn_params)
  File "C:\Users\Davide\Documents\Proyectos Python\aquanode\env\lib\site-packages\django\utils\asyncio.py", line 26, in inner
    return func(*args, **kwargs)
  File "C:\Users\Davide\Documents\Proyectos Python\aquanode\env\lib\site-packages\django\db\backends\postgresql\base.py", line 215, in get_new_connection
    connection = Database.connect(**conn_params)
  File "C:\Users\Davide\Documents\Proyectos Python\aquanode\env\lib\site-packages\psycopg2\__init__.py", line 122, in connect
    conn = _connect(dsn, connection_factory=connection_factory, **kwasync)
psycopg2.OperationalError: could not translate host name "aquadb.cngcu6yaowyr.us-east-2.rds.amazonaws.com" to address: Host desconocido. 


The above exception was the direct cause of the following exception:

Traceback (most recent call last):
  File "C:\Users\Davide\Documents\Proyectos Python\aquanode\env\lib\site-packages\django\core\handlers\exception.py", line 55, in inner
    response = get_response(request)
  File "C:\Users\Davide\Documents\Proyectos Python\aquanode\env\lib\site-packages\django\core\handlers\base.py", line 197, in _get_response
    response = wrapped_callback(request, *callback_args, **callback_kwargs)
  File "C:\Users\Davide\Documents\Proyectos Python\aquanode\env\lib\site-packages\django\views\decorators\csrf.py", line 54, in wrapped_view
    return view_func(*args, **kwargs)
  File "C:\Users\Davide\Documents\Proyectos Python\aquanode\env\lib\site-packages\django\views\generic\base.py", line 103, in view
    return self.dispatch(request, *args, **kwargs)
  File "C:\Users\Davide\Documents\Proyectos Python\aquanode\env\lib\site-packages\rest_framework\views.py", line 509, in dispatch
    response = self.handle_exception(exc)
  File "C:\Users\Davide\Documents\Proyectos Python\aquanode\env\lib\site-packages\rest_framework\views.py", line 469, in handle_exception
    self.raise_uncaught_exception(exc)
  File "C:\Users\Davide\Documents\Proyectos Python\aquanode\env\lib\site-packages\rest_framework\views.py", line 480, in raise_uncaught_exception
    raise exc
  File "C:\Users\Davide\Documents\Proyectos Python\aquanode\env\lib\site-packages\rest_framework\views.py", line 497, in dispatch
    self.initial(request, *args, **kwargs)
  File "C:\Users\Davide\Documents\Proyectos Python\aquanode\env\lib\site-packages\rest_framework\views.py", line 414, in initial
    self.perform_authentication(request)
  File "C:\Users\Davide\Documents\Proyectos Python\aquanode\env\lib\site-packages\rest_framework\views.py", line 324, in perform_authentication
    request.user
  File "C:\Users\Davide\Documents\Proyectos Python\aquanode\env\lib\site-packages\rest_framework\request.py", line 231, in user
    self._authenticate()
  File "C:\Users\Davide\Documents\Proyectos Python\aquanode\env\lib\site-packages\rest_framework\request.py", line 384, in _authenticate
    user_auth_tuple = authenticator.authenticate(self)
  File "C:\Users\Davide\Documents\Proyectos Python\aquanode\env\lib\site-packages\rest_framework_simplejwt\authentication.py", line 51, in authenticate
    return self.get_user(validated_token), validated_token
  File "C:\Users\Davide\Documents\Proyectos Python\aquanode\env\lib\site-packages\rest_framework_simplejwt\authentication.py", line 130, in get_user
    user = self.user_model.objects.get(**{api_settings.USER_ID_FIELD: user_id})
  File "C:\Users\Davide\Documents\Proyectos Python\aquanode\env\lib\site-packages\django\db\models\manager.py", line 85, in manager_method
    return getattr(self.get_queryset(), name)(*args, **kwargs)
  File "C:\Users\Davide\Documents\Proyectos Python\aquanode\env\lib\site-packages\django\db\models\query.py", line 646, in get
    num = len(clone)
  File "C:\Users\Davide\Documents\Proyectos Python\aquanode\env\lib\site-packages\django\db\models\query.py", line 376, in __len__
    self._fetch_all()
  File "C:\Users\Davide\Documents\Proyectos Python\aquanode\env\lib\site-packages\django\db\models\query.py", line 1866, in _fetch_all
    self._result_cache = list(self._iterable_class(self))
  File "C:\Users\Davide\Documents\Proyectos Python\aquanode\env\lib\site-packages\django\db\models\query.py", line 87, in __iter__
    results = compiler.execute_sql(
  File "C:\Users\Davide\Documents\Proyectos Python\aquanode\env\lib\site-packages\django\db\models\sql\compiler.py", line 1393, in execute_sql
    cursor = self.connection.cursor()
  File "C:\Users\Davide\Documents\Proyectos Python\aquanode\env\lib\site-packages\django\utils\asyncio.py", line 26, in inner
    return func(*args, **kwargs)
  File "C:\Users\Davide\Documents\Proyectos Python\aquanode\env\lib\site-packages\django\db\backends\base\base.py", line 323, in cursor
    return self._cursor()
  File "C:\Users\Davide\Documents\Proyectos Python\aquanode\env\lib\site-packages\django\db\backends\base\base.py", line 299, in _cursor
    self.ensure_connection()
  File "C:\Users\Davide\Documents\Proyectos Python\aquanode\env\lib\site-packages\django\utils\asyncio.py", line 26, in inner
    return func(*args, **kwargs)
  File "C:\Users\Davide\Documents\Proyectos Python\aquanode\env\lib\site-packages\django\db\backends\base\base.py", line 281, in ensure_connection
    with self.wrap_database_errors:
  File "C:\Users\Davide\Documents\Proyectos Python\aquanode\env\lib\site-packages\django\db\utils.py", line 91, in __exit__
    raise dj_exc_value.with_traceback(traceback) from exc_value
  File "C:\Users\Davide\Documents\Proyectos Python\aquanode\env\lib\site-packages\django\db\backends\base\base.py", line 282, in ensure_connection
    self.connect()
  File "C:\Users\Davide\Documents\Proyectos Python\aquanode\env\lib\site-packages\django\utils\asyncio.py", line 26, in inner
    return func(*args, **kwargs)
  File "C:\Users\Davide\Documents\Proyectos Python\aquanode\env\lib\site-packages\django\db\backends\base\base.py", line 263, in connect
    self.connection = self.get_new_connection(conn_params)
  File "C:\Users\Davide\Documents\Proyectos Python\aquanode\env\lib\site-packages\django\utils\asyncio.py", line 26, in inner
    return func(*args, **kwargs)
  File "C:\Users\Davide\Documents\Proyectos Python\aquanode\env\lib\site-packages\django\db\backends\postgresql\base.py", line 215, in get_new_connection
    connection = Database.connect(**conn_params)
  File "C:\Users\Davide\Documents\Proyectos Python\aquanode\env\lib\site-packages\psycopg2\__init__.py", line 122, in connect
    conn = _connect(dsn, connection_factory=connection_factory, **kwasync)
django.db.utils.OperationalError: could not translate host name "aquadb.cngcu6yaowyr.us-east-2.rds.amazonaws.com" to address: Host desconocido. 

"GET /api/users/list/ HTTP/1.1" 500 221670
Internal Server Error: /api/roles/list/
Traceback (most recent call last):
  File "C:\Users\Davide\Documents\Proyectos Python\aquanode\env\lib\site-packages\django\db\backends\base\base.py", line 282, in ensure_connection
    self.connect()
  File "C:\Users\Davide\Documents\Proyectos Python\aquanode\env\lib\site-packages\django\utils\asyncio.py", line 26, in inner
    return func(*args, **kwargs)
  File "C:\Users\Davide\Documents\Proyectos Python\aquanode\env\lib\site-packages\django\db\backends\base\base.py", line 263, in connect
    self.connection = self.get_new_connection(conn_params)
  File "C:\Users\Davide\Documents\Proyectos Python\aquanode\env\lib\site-packages\django\utils\asyncio.py", line 26, in inner
    return func(*args, **kwargs)
  File "C:\Users\Davide\Documents\Proyectos Python\aquanode\env\lib\site-packages\django\db\backends\postgresql\base.py", line 215, in get_new_connection
    connection = Database.connect(**conn_params)
  File "C:\Users\Davide\Documents\Proyectos Python\aquanode\env\lib\site-packages\psycopg2\__init__.py", line 122, in connect
    conn = _connect(dsn, connection_factory=connection_factory, **kwasync)
psycopg2.OperationalError: could not translate host name "aquadb.cngcu6yaowyr.us-east-2.rds.amazonaws.com" to address: Host desconocido. 


The above exception was the direct cause of the following exception:

Traceback (most recent call last):
  File "C:\Users\Davide\Documents\Proyectos Python\aquanode\env\lib\site-packages\django\core\handlers\exception.py", line 55, in inner
    response = get_response(request)
  File "C:\Users\Davide\Documents\Proyectos Python\aquanode\env\lib\site-packages\django\core\handlers\base.py", line 197, in _get_response
    response = wrapped_callback(request, *callback_args, **callback_kwargs)
  File "C:\Users\Davide\Documents\Proyectos Python\aquanode\env\lib\site-packages\django\views\decorators\csrf.py", line 54, in wrapped_view
    return view_func(*args, **kwargs)
  File "C:\Users\Davide\Documents\Proyectos Python\aquanode\env\lib\site-packages\django\views\generic\base.py", line 103, in view
    return self.dispatch(request, *args, **kwargs)
  File "C:\Users\Davide\Documents\Proyectos Python\aquanode\env\lib\site-packages\rest_framework\views.py", line 509, in dispatch
    response = self.handle_exception(exc)
  File "C:\Users\Davide\Documents\Proyectos Python\aquanode\env\lib\site-packages\rest_framework\views.py", line 469, in handle_exception
    self.raise_uncaught_exception(exc)
  File "C:\Users\Davide\Documents\Proyectos Python\aquanode\env\lib\site-packages\rest_framework\views.py", line 480, in raise_uncaught_exception
    raise exc
  File "C:\Users\Davide\Documents\Proyectos Python\aquanode\env\lib\site-packages\rest_framework\views.py", line 497, in dispatch
    self.initial(request, *args, **kwargs)
  File "C:\Users\Davide\Documents\Proyectos Python\aquanode\env\lib\site-packages\rest_framework\views.py", line 414, in initial
    self.perform_authentication(request)
  File "C:\Users\Davide\Documents\Proyectos Python\aquanode\env\lib\site-packages\rest_framework\views.py", line 324, in perform_authentication
    request.user
  File "C:\Users\Davide\Documents\Proyectos Python\aquanode\env\lib\site-packages\rest_framework\request.py", line 231, in user
    self._authenticate()
  File "C:\Users\Davide\Documents\Proyectos Python\aquanode\env\lib\site-packages\rest_framework\request.py", line 384, in _authenticate
    user_auth_tuple = authenticator.authenticate(self)
  File "C:\Users\Davide\Documents\Proyectos Python\aquanode\env\lib\site-packages\rest_framework_simplejwt\authentication.py", line 51, in authenticate
    return self.get_user(validated_token), validated_token
  File "C:\Users\Davide\Documents\Proyectos Python\aquanode\env\lib\site-packages\rest_framework_simplejwt\authentication.py", line 130, in get_user
    user = self.user_model.objects.get(**{api_settings.USER_ID_FIELD: user_id})
  File "C:\Users\Davide\Documents\Proyectos Python\aquanode\env\lib\site-packages\django\db\models\manager.py", line 85, in manager_method
    return getattr(self.get_queryset(), name)(*args, **kwargs)
  File "C:\Users\Davide\Documents\Proyectos Python\aquanode\env\lib\site-packages\django\db\models\query.py", line 646, in get
    num = len(clone)
  File "C:\Users\Davide\Documents\Proyectos Python\aquanode\env\lib\site-packages\django\db\models\query.py", line 376, in __len__
    self._fetch_all()
  File "C:\Users\Davide\Documents\Proyectos Python\aquanode\env\lib\site-packages\django\db\models\query.py", line 1866, in _fetch_all
    self._result_cache = list(self._iterable_class(self))
  File "C:\Users\Davide\Documents\Proyectos Python\aquanode\env\lib\site-packages\django\db\models\query.py", line 87, in __iter__
    results = compiler.execute_sql(
  File "C:\Users\Davide\Documents\Proyectos Python\aquanode\env\lib\site-packages\django\db\models\sql\compiler.py", line 1393, in execute_sql
    cursor = self.connection.cursor()
  File "C:\Users\Davide\Documents\Proyectos Python\aquanode\env\lib\site-packages\django\utils\asyncio.py", line 26, in inner
    return func(*args, **kwargs)
  File "C:\Users\Davide\Documents\Proyectos Python\aquanode\env\lib\site-packages\django\db\backends\base\base.py", line 323, in cursor
    return self._cursor()
  File "C:\Users\Davide\Documents\Proyectos Python\aquanode\env\lib\site-packages\django\db\backends\base\base.py", line 299, in _cursor
    self.ensure_connection()
  File "C:\Users\Davide\Documents\Proyectos Python\aquanode\env\lib\site-packages\django\utils\asyncio.py", line 26, in inner
    return func(*args, **kwargs)
  File "C:\Users\Davide\Documents\Proyectos Python\aquanode\env\lib\site-packages\django\db\backends\base\base.py", line 281, in ensure_connection
    with self.wrap_database_errors:
  File "C:\Users\Davide\Documents\Proyectos Python\aquanode\env\lib\site-packages\django\db\utils.py", line 91, in __exit__
    raise dj_exc_value.with_traceback(traceback) from exc_value
  File "C:\Users\Davide\Documents\Proyectos Python\aquanode\env\lib\site-packages\django\db\backends\base\base.py", line 282, in ensure_connection
    self.connect()
  File "C:\Users\Davide\Documents\Proyectos Python\aquanode\env\lib\site-packages\django\utils\asyncio.py", line 26, in inner
    return func(*args, **kwargs)
  File "C:\Users\Davide\Documents\Proyectos Python\aquanode\env\lib\site-packages\django\db\backends\base\base.py", line 263, in connect
    self.connection = self.get_new_connection(conn_params)
  File "C:\Users\Davide\Documents\Proyectos Python\aquanode\env\lib\site-packages\django\utils\asyncio.py", line 26, in inner
    return func(*args, **kwargs)
  File "C:\Users\Davide\Documents\Proyectos Python\aquanode\env\lib\site-packages\django\db\backends\postgresql\base.py", line 215, in get_new_connection
    connection = Database.connect(**conn_params)
  File "C:\Users\Davide\Documents\Proyectos Python\aquanode\env\lib\site-packages\psycopg2\__init__.py", line 122, in connect
    conn = _connect(dsn, connection_factory=connection_factory, **kwasync)
django.db.utils.OperationalError: could not translate host name "aquadb.cngcu6yaowyr.us-east-2.rds.amazonaws.com" to address: Host desconocido. 

"GET /api/roles/list/ HTTP/1.1" 500 221269
Internal Server Error: /api/users/detail/1/
Traceback (most recent call last):
  File "C:\Users\Davide\Documents\Proyectos Python\aquanode\env\lib\site-packages\django\db\backends\base\base.py", line 282, in ensure_connection
    self.connect()
  File "C:\Users\Davide\Documents\Proyectos Python\aquanode\env\lib\site-packages\django\utils\asyncio.py", line 26, in inner
    return func(*args, **kwargs)
  File "C:\Users\Davide\Documents\Proyectos Python\aquanode\env\lib\site-packages\django\db\backends\base\base.py", line 263, in connect
    self.connection = self.get_new_connection(conn_params)
  File "C:\Users\Davide\Documents\Proyectos Python\aquanode\env\lib\site-packages\django\utils\asyncio.py", line 26, in inner
    return func(*args, **kwargs)
  File "C:\Users\Davide\Documents\Proyectos Python\aquanode\env\lib\site-packages\django\db\backends\postgresql\base.py", line 215, in get_new_connection
    connection = Database.connect(**conn_params)
  File "C:\Users\Davide\Documents\Proyectos Python\aquanode\env\lib\site-packages\psycopg2\__init__.py", line 122, in connect
    conn = _connect(dsn, connection_factory=connection_factory, **kwasync)
psycopg2.OperationalError: could not translate host name "aquadb.cngcu6yaowyr.us-east-2.rds.amazonaws.com" to address: Host desconocido. 


The above exception was the direct cause of the following exception:

Traceback (most recent call last):
  File "C:\Users\Davide\Documents\Proyectos Python\aquanode\env\lib\site-packages\django\core\handlers\exception.py", line 55, in inner
    response = get_response(request)
  File "C:\Users\Davide\Documents\Proyectos Python\aquanode\env\lib\site-packages\django\core\handlers\base.py", line 197, in _get_response
    response = wrapped_callback(request, *callback_args, **callback_kwargs)
  File "C:\Users\Davide\Documents\Proyectos Python\aquanode\env\lib\site-packages\django\views\decorators\csrf.py", line 54, in wrapped_view
    return view_func(*args, **kwargs)
  File "C:\Users\Davide\Documents\Proyectos Python\aquanode\env\lib\site-packages\django\views\generic\base.py", line 103, in view
    return self.dispatch(request, *args, **kwargs)
  File "C:\Users\Davide\Documents\Proyectos Python\aquanode\env\lib\site-packages\rest_framework\views.py", line 509, in dispatch
    response = self.handle_exception(exc)
  File "C:\Users\Davide\Documents\Proyectos Python\aquanode\env\lib\site-packages\rest_framework\views.py", line 469, in handle_exception
    self.raise_uncaught_exception(exc)
  File "C:\Users\Davide\Documents\Proyectos Python\aquanode\env\lib\site-packages\rest_framework\views.py", line 480, in raise_uncaught_exception
    raise exc
  File "C:\Users\Davide\Documents\Proyectos Python\aquanode\env\lib\site-packages\rest_framework\views.py", line 497, in dispatch
    self.initial(request, *args, **kwargs)
  File "C:\Users\Davide\Documents\Proyectos Python\aquanode\env\lib\site-packages\rest_framework\views.py", line 414, in initial
    self.perform_authentication(request)
  File "C:\Users\Davide\Documents\Proyectos Python\aquanode\env\lib\site-packages\rest_framework\views.py", line 324, in perform_authentication
    request.user
  File "C:\Users\Davide\Documents\Proyectos Python\aquanode\env\lib\site-packages\rest_framework\request.py", line 231, in user
    self._authenticate()
  File "C:\Users\Davide\Documents\Proyectos Python\aquanode\env\lib\site-packages\rest_framework\request.py", line 384, in _authenticate
    user_auth_tuple = authenticator.authenticate(self)
  File "C:\Users\Davide\Documents\Proyectos Python\aquanode\env\lib\site-packages\rest_framework_simplejwt\authentication.py", line 51, in authenticate
    return self.get_user(validated_token), validated_token
  File "C:\Users\Davide\Documents\Proyectos Python\aquanode\env\lib\site-packages\rest_framework_simplejwt\authentication.py", line 130, in get_user
    user = self.user_model.objects.get(**{api_settings.USER_ID_FIELD: user_id})
  File "C:\Users\Davide\Documents\Proyectos Python\aquanode\env\lib\site-packages\django\db\models\manager.py", line 85, in manager_method
    return getattr(self.get_queryset(), name)(*args, **kwargs)
  File "C:\Users\Davide\Documents\Proyectos Python\aquanode\env\lib\site-packages\django\db\models\query.py", line 646, in get
    num = len(clone)
  File "C:\Users\Davide\Documents\Proyectos Python\aquanode\env\lib\site-packages\django\db\models\query.py", line 376, in __len__
    self._fetch_all()
  File "C:\Users\Davide\Documents\Proyectos Python\aquanode\env\lib\site-packages\django\db\models\query.py", line 1866, in _fetch_all
    self._result_cache = list(self._iterable_class(self))
  File "C:\Users\Davide\Documents\Proyectos Python\aquanode\env\lib\site-packages\django\db\models\query.py", line 87, in __iter__
    results = compiler.execute_sql(
  File "C:\Users\Davide\Documents\Proyectos Python\aquanode\env\lib\site-packages\django\db\models\sql\compiler.py", line 1393, in execute_sql
    cursor = self.connection.cursor()
  File "C:\Users\Davide\Documents\Proyectos Python\aquanode\env\lib\site-packages\django\utils\asyncio.py", line 26, in inner
    return func(*args, **kwargs)
  File "C:\Users\Davide\Documents\Proyectos Python\aquanode\env\lib\site-packages\django\db\backends\base\base.py", line 323, in cursor
    return self._cursor()
  File "C:\Users\Davide\Documents\Proyectos Python\aquanode\env\lib\site-packages\django\db\backends\base\base.py", line 299, in _cursor
    self.ensure_connection()
  File "C:\Users\Davide\Documents\Proyectos Python\aquanode\env\lib\site-packages\django\utils\asyncio.py", line 26, in inner
    return func(*args, **kwargs)
  File "C:\Users\Davide\Documents\Proyectos Python\aquanode\env\lib\site-packages\django\db\backends\base\base.py", line 281, in ensure_connection
    with self.wrap_database_errors:
  File "C:\Users\Davide\Documents\Proyectos Python\aquanode\env\lib\site-packages\django\db\utils.py", line 91, in __exit__
    raise dj_exc_value.with_traceback(traceback) from exc_value
  File "C:\Users\Davide\Documents\Proyectos Python\aquanode\env\lib\site-packages\django\db\backends\base\base.py", line 282, in ensure_connection
    self.connect()
  File "C:\Users\Davide\Documents\Proyectos Python\aquanode\env\lib\site-packages\django\utils\asyncio.py", line 26, in inner
    return func(*args, **kwargs)
  File "C:\Users\Davide\Documents\Proyectos Python\aquanode\env\lib\site-packages\django\db\backends\base\base.py", line 263, in connect
    self.connection = self.get_new_connection(conn_params)
  File "C:\Users\Davide\Documents\Proyectos Python\aquanode\env\lib\site-packages\django\utils\asyncio.py", line 26, in inner
    return func(*args, **kwargs)
  File "C:\Users\Davide\Documents\Proyectos Python\aquanode\env\lib\site-packages\django\db\backends\postgresql\base.py", line 215, in get_new_connection
    connection = Database.connect(**conn_params)
  File "C:\Users\Davide\Documents\Proyectos Python\aquanode\env\lib\site-packages\psycopg2\__init__.py", line 122, in connect
    conn = _connect(dsn, connection_factory=connection_factory, **kwasync)
django.db.utils.OperationalError: could not translate host name "aquadb.cngcu6yaowyr.us-east-2.rds.amazonaws.com" to address: Host desconocido. 

"GET /api/users/detail/1/ HTTP/1.1" 500 221467
Internal Server Error: /api/diagnosis/register_event/
Traceback (most recent call last):
  File "C:\Users\Davide\Documents\Proyectos Python\aquanode\env\lib\site-packages\django\core\handlers\exception.py", line 55, in inner
    response = get_response(request)
  File "C:\Users\Davide\Documents\Proyectos Python\aquanode\env\lib\site-packages\django\core\handlers\base.py", line 197, in _get_response
    response = wrapped_callback(request, *callback_args, **callback_kwargs)
  File "C:\Users\Davide\Documents\Proyectos Python\aquanode\env\lib\site-packages\django\views\decorators\csrf.py", line 54, in wrapped_view
    return view_func(*args, **kwargs)
  File "C:\Users\Davide\Documents\Proyectos Python\aquanode\env\lib\site-packages\django\views\generic\base.py", line 103, in view
    return self.dispatch(request, *args, **kwargs)
  File "C:\Users\Davide\Documents\Proyectos Python\aquanode\env\lib\site-packages\rest_framework\views.py", line 509, in dispatch
    response = self.handle_exception(exc)
  File "C:\Users\Davide\Documents\Proyectos Python\aquanode\env\lib\site-packages\rest_framework\views.py", line 469, in handle_exception
    self.raise_uncaught_exception(exc)
  File "C:\Users\Davide\Documents\Proyectos Python\aquanode\env\lib\site-packages\rest_framework\views.py", line 480, in raise_uncaught_exception
    raise exc
  File "C:\Users\Davide\Documents\Proyectos Python\aquanode\env\lib\site-packages\rest_framework\views.py", line 506, in dispatch
    response = handler(request, *args, **kwargs)
  File "C:\Users\Davide\Documents\Proyectos Python\aquanode\env\lib\site-packages\rest_framework\decorators.py", line 50, in handler
    return func(*args, **kwargs)
  File "C:\Users\Davide\Documents\Proyectos Python\aquanode\aquanode\core\diagnosis\views.py", line 37, in register_events
    print("Los datos de token son: ", tokens.query)
AttributeError: 'list' object has no attribute 'query'
"POST /api/diagnosis/register_event/ HTTP/1.1" 500 103177
Internal Server Error: /api/diagnosis/notifications/
Traceback (most recent call last):
  File "C:\Users\Davide\Documents\Proyectos Python\aquanode\env\lib\site-packages\django\core\handlers\exception.py", line 55, in inner
    response = get_response(request)
  File "C:\Users\Davide\Documents\Proyectos Python\aquanode\env\lib\site-packages\django\core\handlers\base.py", line 220, in _get_response
    response = response.render()
  File "C:\Users\Davide\Documents\Proyectos Python\aquanode\env\lib\site-packages\django\template\response.py", line 114, in render
    self.content = self.rendered_content
  File "C:\Users\Davide\Documents\Proyectos Python\aquanode\env\lib\site-packages\rest_framework\response.py", line 74, in rendered_content
    ret = renderer.render(self.data, accepted_media_type, context)
  File "C:\Users\Davide\Documents\Proyectos Python\aquanode\env\lib\site-packages\rest_framework\renderers.py", line 100, in render
    ret = json.dumps(
  File "C:\Users\Davide\Documents\Proyectos Python\aquanode\env\lib\site-packages\rest_framework\utils\json.py", line 25, in dumps
    return json.dumps(*args, **kwargs)
  File "C:\Users\Davide\AppData\Local\Programs\Python\Python310\lib\json\__init__.py", line 238, in dumps
    **kw).encode(obj)
  File "C:\Users\Davide\AppData\Local\Programs\Python\Python310\lib\json\encoder.py", line 199, in encode
    chunks = self.iterencode(o, _one_shot=True)
  File "C:\Users\Davide\AppData\Local\Programs\Python\Python310\lib\json\encoder.py", line 257, in iterencode
    return _iterencode(o, 0)
  File "C:\Users\Davide\Documents\Proyectos Python\aquanode\env\lib\site-packages\rest_framework\utils\encoders.py", line 52, in default
    return obj.decode()
UnicodeDecodeError: 'utf-8' codec can't decode byte 0xbf in position 38: invalid start byte
"GET /api/diagnosis/notifications/ HTTP/1.1" 500 135726
Internal Server Error: /api/diagnosis/notifications/
Traceback (most recent call last):
  File "C:\Users\Davide\Documents\Proyectos Python\aquanode\env\lib\site-packages\django\core\handlers\exception.py", line 55, in inner
    response = get_response(request)
  File "C:\Users\Davide\Documents\Proyectos Python\aquanode\env\lib\site-packages\django\core\handlers\base.py", line 220, in _get_response
    response = response.render()
  File "C:\Users\Davide\Documents\Proyectos Python\aquanode\env\lib\site-packages\django\template\response.py", line 114, in render
    self.content = self.rendered_content
  File "C:\Users\Davide\Documents\Proyectos Python\aquanode\env\lib\site-packages\rest_framework\response.py", line 74, in rendered_content
    ret = renderer.render(self.data, accepted_media_type, context)
  File "C:\Users\Davide\Documents\Proyectos Python\aquanode\env\lib\site-packages\rest_framework\renderers.py", line 100, in render
    ret = json.dumps(
  File "C:\Users\Davide\Documents\Proyectos Python\aquanode\env\lib\site-packages\rest_framework\utils\json.py", line 25, in dumps
    return json.dumps(*args, **kwargs)
  File "C:\Users\Davide\AppData\Local\Programs\Python\Python310\lib\json\__init__.py", line 238, in dumps
    **kw).encode(obj)
  File "C:\Users\Davide\AppData\Local\Programs\Python\Python310\lib\json\encoder.py", line 199, in encode
    chunks = self.iterencode(o, _one_shot=True)
  File "C:\Users\Davide\AppData\Local\Programs\Python\Python310\lib\json\encoder.py", line 257, in iterencode
    return _iterencode(o, 0)
  File "C:\Users\Davide\Documents\Proyectos Python\aquanode\env\lib\site-packages\rest_framework\utils\encoders.py", line 52, in default
    return obj.decode()
UnicodeDecodeError: 'utf-8' codec can't decode byte 0xbf in position 38: invalid start byte
"GET /api/diagnosis/notifications/ HTTP/1.1" 500 135686
Internal Server Error: /api/diagnosis/notifications/
Traceback (most recent call last):
  File "C:\Users\Davide\Documents\Proyectos Python\aquanode\env\lib\site-packages\django\core\handlers\exception.py", line 55, in inner
    response = get_response(request)
  File "C:\Users\Davide\Documents\Proyectos Python\aquanode\env\lib\site-packages\django\core\handlers\base.py", line 220, in _get_response
    response = response.render()
  File "C:\Users\Davide\Documents\Proyectos Python\aquanode\env\lib\site-packages\django\template\response.py", line 114, in render
    self.content = self.rendered_content
  File "C:\Users\Davide\Documents\Proyectos Python\aquanode\env\lib\site-packages\rest_framework\response.py", line 74, in rendered_content
    ret = renderer.render(self.data, accepted_media_type, context)
  File "C:\Users\Davide\Documents\Proyectos Python\aquanode\env\lib\site-packages\rest_framework\renderers.py", line 100, in render
    ret = json.dumps(
  File "C:\Users\Davide\Documents\Proyectos Python\aquanode\env\lib\site-packages\rest_framework\utils\json.py", line 25, in dumps
    return json.dumps(*args, **kwargs)
  File "C:\Users\Davide\AppData\Local\Programs\Python\Python310\lib\json\__init__.py", line 238, in dumps
    **kw).encode(obj)
  File "C:\Users\Davide\AppData\Local\Programs\Python\Python310\lib\json\encoder.py", line 199, in encode
    chunks = self.iterencode(o, _one_shot=True)
  File "C:\Users\Davide\AppData\Local\Programs\Python\Python310\lib\json\encoder.py", line 257, in iterencode
    return _iterencode(o, 0)
  File "C:\Users\Davide\Documents\Proyectos Python\aquanode\env\lib\site-packages\rest_framework\utils\encoders.py", line 52, in default
    return obj.decode()
UnicodeDecodeError: 'utf-8' codec can't decode byte 0xbf in position 38: invalid start byte
"GET /api/diagnosis/notifications/ HTTP/1.1" 500 135686
Internal Server Error: /api/diagnosis/notifications/
Traceback (most recent call last):
  File "C:\Users\Davide\Documents\Proyectos Python\aquanode\env\lib\site-packages\django\core\handlers\exception.py", line 55, in inner
    response = get_response(request)
  File "C:\Users\Davide\Documents\Proyectos Python\aquanode\env\lib\site-packages\django\core\handlers\base.py", line 220, in _get_response
    response = response.render()
  File "C:\Users\Davide\Documents\Proyectos Python\aquanode\env\lib\site-packages\django\template\response.py", line 114, in render
    self.content = self.rendered_content
  File "C:\Users\Davide\Documents\Proyectos Python\aquanode\env\lib\site-packages\rest_framework\response.py", line 74, in rendered_content
    ret = renderer.render(self.data, accepted_media_type, context)
  File "C:\Users\Davide\Documents\Proyectos Python\aquanode\env\lib\site-packages\rest_framework\renderers.py", line 727, in render
    context = self.get_context(data, accepted_media_type, renderer_context)
  File "C:\Users\Davide\Documents\Proyectos Python\aquanode\env\lib\site-packages\rest_framework\renderers.py", line 683, in get_context
    'content': self.get_content(renderer, data, accepted_media_type, renderer_context),
  File "C:\Users\Davide\Documents\Proyectos Python\aquanode\env\lib\site-packages\rest_framework\renderers.py", line 413, in get_content
    content = renderer.render(data, accepted_media_type, renderer_context)
  File "C:\Users\Davide\Documents\Proyectos Python\aquanode\env\lib\site-packages\rest_framework\renderers.py", line 100, in render
    ret = json.dumps(
  File "C:\Users\Davide\Documents\Proyectos Python\aquanode\env\lib\site-packages\rest_framework\utils\json.py", line 25, in dumps
    return json.dumps(*args, **kwargs)
  File "C:\Users\Davide\AppData\Local\Programs\Python\Python310\lib\json\__init__.py", line 238, in dumps
    **kw).encode(obj)
  File "C:\Users\Davide\AppData\Local\Programs\Python\Python310\lib\json\encoder.py", line 201, in encode
    chunks = list(chunks)
  File "C:\Users\Davide\AppData\Local\Programs\Python\Python310\lib\json\encoder.py", line 429, in _iterencode
    yield from _iterencode_list(o, _current_indent_level)
  File "C:\Users\Davide\AppData\Local\Programs\Python\Python310\lib\json\encoder.py", line 325, in _iterencode_list
    yield from chunks
  File "C:\Users\Davide\AppData\Local\Programs\Python\Python310\lib\json\encoder.py", line 405, in _iterencode_dict
    yield from chunks
  File "C:\Users\Davide\AppData\Local\Programs\Python\Python310\lib\json\encoder.py", line 439, in _iterencode
    yield from _iterencode(o, _current_indent_level)
  File "C:\Users\Davide\AppData\Local\Programs\Python\Python310\lib\json\encoder.py", line 429, in _iterencode
    yield from _iterencode_list(o, _current_indent_level)
  File "C:\Users\Davide\AppData\Local\Programs\Python\Python310\lib\json\encoder.py", line 325, in _iterencode_list
    yield from chunks
  File "C:\Users\Davide\AppData\Local\Programs\Python\Python310\lib\json\encoder.py", line 438, in _iterencode
    o = _default(o)
  File "C:\Users\Davide\Documents\Proyectos Python\aquanode\env\lib\site-packages\rest_framework\utils\encoders.py", line 52, in default
    return obj.decode()
UnicodeDecodeError: 'utf-8' codec can't decode byte 0xbf in position 38: invalid start byte
"GET /api/diagnosis/notifications/ HTTP/1.1" 500 273895
Internal Server Error: /api/diagnosis/notifications/
Traceback (most recent call last):
  File "C:\Users\Davide\Documents\Proyectos Python\aquanode\env\lib\site-packages\django\core\handlers\exception.py", line 55, in inner
    response = get_response(request)
  File "C:\Users\Davide\Documents\Proyectos Python\aquanode\env\lib\site-packages\django\core\handlers\base.py", line 220, in _get_response
    response = response.render()
  File "C:\Users\Davide\Documents\Proyectos Python\aquanode\env\lib\site-packages\django\template\response.py", line 114, in render
    self.content = self.rendered_content
  File "C:\Users\Davide\Documents\Proyectos Python\aquanode\env\lib\site-packages\rest_framework\response.py", line 74, in rendered_content
    ret = renderer.render(self.data, accepted_media_type, context)
  File "C:\Users\Davide\Documents\Proyectos Python\aquanode\env\lib\site-packages\rest_framework\renderers.py", line 727, in render
    context = self.get_context(data, accepted_media_type, renderer_context)
  File "C:\Users\Davide\Documents\Proyectos Python\aquanode\env\lib\site-packages\rest_framework\renderers.py", line 683, in get_context
    'content': self.get_content(renderer, data, accepted_media_type, renderer_context),
  File "C:\Users\Davide\Documents\Proyectos Python\aquanode\env\lib\site-packages\rest_framework\renderers.py", line 413, in get_content
    content = renderer.render(data, accepted_media_type, renderer_context)
  File "C:\Users\Davide\Documents\Proyectos Python\aquanode\env\lib\site-packages\rest_framework\renderers.py", line 100, in render
    ret = json.dumps(
  File "C:\Users\Davide\Documents\Proyectos Python\aquanode\env\lib\site-packages\rest_framework\utils\json.py", line 25, in dumps
    return json.dumps(*args, **kwargs)
  File "C:\Users\Davide\AppData\Local\Programs\Python\Python310\lib\json\__init__.py", line 238, in dumps
    **kw).encode(obj)
  File "C:\Users\Davide\AppData\Local\Programs\Python\Python310\lib\json\encoder.py", line 201, in encode
    chunks = list(chunks)
  File "C:\Users\Davide\AppData\Local\Programs\Python\Python310\lib\json\encoder.py", line 429, in _iterencode
    yield from _iterencode_list(o, _current_indent_level)
  File "C:\Users\Davide\AppData\Local\Programs\Python\Python310\lib\json\encoder.py", line 325, in _iterencode_list
    yield from chunks
  File "C:\Users\Davide\AppData\Local\Programs\Python\Python310\lib\json\encoder.py", line 405, in _iterencode_dict
    yield from chunks
  File "C:\Users\Davide\AppData\Local\Programs\Python\Python310\lib\json\encoder.py", line 439, in _iterencode
    yield from _iterencode(o, _current_indent_level)
  File "C:\Users\Davide\AppData\Local\Programs\Python\Python310\lib\json\encoder.py", line 429, in _iterencode
    yield from _iterencode_list(o, _current_indent_level)
  File "C:\Users\Davide\AppData\Local\Programs\Python\Python310\lib\json\encoder.py", line 325, in _iterencode_list
    yield from chunks
  File "C:\Users\Davide\AppData\Local\Programs\Python\Python310\lib\json\encoder.py", line 438, in _iterencode
    o = _default(o)
  File "C:\Users\Davide\Documents\Proyectos Python\aquanode\env\lib\site-packages\rest_framework\utils\encoders.py", line 52, in default
    return obj.decode()
UnicodeDecodeError: 'utf-8' codec can't decode byte 0xbf in position 38: invalid start byte
"GET /api/diagnosis/notifications/ HTTP/1.1" 500 273895
Internal Server Error: /api/diagnosis/notifications/
Traceback (most recent call last):
  File "C:\Users\Davide\Documents\Proyectos Python\aquanode\env\lib\site-packages\django\core\handlers\exception.py", line 55, in inner
    response = get_response(request)
  File "C:\Users\Davide\Documents\Proyectos Python\aquanode\env\lib\site-packages\django\core\handlers\base.py", line 220, in _get_response
    response = response.render()
  File "C:\Users\Davide\Documents\Proyectos Python\aquanode\env\lib\site-packages\django\template\response.py", line 114, in render
    self.content = self.rendered_content
  File "C:\Users\Davide\Documents\Proyectos Python\aquanode\env\lib\site-packages\rest_framework\response.py", line 74, in rendered_content
    ret = renderer.render(self.data, accepted_media_type, context)
  File "C:\Users\Davide\Documents\Proyectos Python\aquanode\env\lib\site-packages\rest_framework\renderers.py", line 727, in render
    context = self.get_context(data, accepted_media_type, renderer_context)
  File "C:\Users\Davide\Documents\Proyectos Python\aquanode\env\lib\site-packages\rest_framework\renderers.py", line 683, in get_context
    'content': self.get_content(renderer, data, accepted_media_type, renderer_context),
  File "C:\Users\Davide\Documents\Proyectos Python\aquanode\env\lib\site-packages\rest_framework\renderers.py", line 413, in get_content
    content = renderer.render(data, accepted_media_type, renderer_context)
  File "C:\Users\Davide\Documents\Proyectos Python\aquanode\env\lib\site-packages\rest_framework\renderers.py", line 100, in render
    ret = json.dumps(
  File "C:\Users\Davide\Documents\Proyectos Python\aquanode\env\lib\site-packages\rest_framework\utils\json.py", line 25, in dumps
    return json.dumps(*args, **kwargs)
  File "C:\Users\Davide\AppData\Local\Programs\Python\Python310\lib\json\__init__.py", line 238, in dumps
    **kw).encode(obj)
  File "C:\Users\Davide\AppData\Local\Programs\Python\Python310\lib\json\encoder.py", line 201, in encode
    chunks = list(chunks)
  File "C:\Users\Davide\AppData\Local\Programs\Python\Python310\lib\json\encoder.py", line 429, in _iterencode
    yield from _iterencode_list(o, _current_indent_level)
  File "C:\Users\Davide\AppData\Local\Programs\Python\Python310\lib\json\encoder.py", line 325, in _iterencode_list
    yield from chunks
  File "C:\Users\Davide\AppData\Local\Programs\Python\Python310\lib\json\encoder.py", line 405, in _iterencode_dict
    yield from chunks
  File "C:\Users\Davide\AppData\Local\Programs\Python\Python310\lib\json\encoder.py", line 439, in _iterencode
    yield from _iterencode(o, _current_indent_level)
  File "C:\Users\Davide\AppData\Local\Programs\Python\Python310\lib\json\encoder.py", line 429, in _iterencode
    yield from _iterencode_list(o, _current_indent_level)
  File "C:\Users\Davide\AppData\Local\Programs\Python\Python310\lib\json\encoder.py", line 325, in _iterencode_list
    yield from chunks
  File "C:\Users\Davide\AppData\Local\Programs\Python\Python310\lib\json\encoder.py", line 438, in _iterencode
    o = _default(o)
  File "C:\Users\Davide\Documents\Proyectos Python\aquanode\env\lib\site-packages\rest_framework\utils\encoders.py", line 52, in default
    return obj.decode()
UnicodeDecodeError: 'utf-8' codec can't decode byte 0xbf in position 38: invalid start byte
"GET /api/diagnosis/notifications/ HTTP/1.1" 500 273895
Internal Server Error: /api/diagnosis/notifications/
Traceback (most recent call last):
  File "C:\Users\Davide\Documents\Proyectos Python\aquanode\env\lib\site-packages\django\core\handlers\exception.py", line 55, in inner
    response = get_response(request)
  File "C:\Users\Davide\Documents\Proyectos Python\aquanode\env\lib\site-packages\django\core\handlers\base.py", line 220, in _get_response
    response = response.render()
  File "C:\Users\Davide\Documents\Proyectos Python\aquanode\env\lib\site-packages\django\template\response.py", line 114, in render
    self.content = self.rendered_content
  File "C:\Users\Davide\Documents\Proyectos Python\aquanode\env\lib\site-packages\rest_framework\response.py", line 74, in rendered_content
    ret = renderer.render(self.data, accepted_media_type, context)
  File "C:\Users\Davide\Documents\Proyectos Python\aquanode\env\lib\site-packages\rest_framework\renderers.py", line 727, in render
    context = self.get_context(data, accepted_media_type, renderer_context)
  File "C:\Users\Davide\Documents\Proyectos Python\aquanode\env\lib\site-packages\rest_framework\renderers.py", line 683, in get_context
    'content': self.get_content(renderer, data, accepted_media_type, renderer_context),
  File "C:\Users\Davide\Documents\Proyectos Python\aquanode\env\lib\site-packages\rest_framework\renderers.py", line 413, in get_content
    content = renderer.render(data, accepted_media_type, renderer_context)
  File "C:\Users\Davide\Documents\Proyectos Python\aquanode\env\lib\site-packages\rest_framework\renderers.py", line 100, in render
    ret = json.dumps(
  File "C:\Users\Davide\Documents\Proyectos Python\aquanode\env\lib\site-packages\rest_framework\utils\json.py", line 25, in dumps
    return json.dumps(*args, **kwargs)
  File "C:\Users\Davide\AppData\Local\Programs\Python\Python310\lib\json\__init__.py", line 238, in dumps
    **kw).encode(obj)
  File "C:\Users\Davide\AppData\Local\Programs\Python\Python310\lib\json\encoder.py", line 201, in encode
    chunks = list(chunks)
  File "C:\Users\Davide\AppData\Local\Programs\Python\Python310\lib\json\encoder.py", line 429, in _iterencode
    yield from _iterencode_list(o, _current_indent_level)
  File "C:\Users\Davide\AppData\Local\Programs\Python\Python310\lib\json\encoder.py", line 325, in _iterencode_list
    yield from chunks
  File "C:\Users\Davide\AppData\Local\Programs\Python\Python310\lib\json\encoder.py", line 405, in _iterencode_dict
    yield from chunks
  File "C:\Users\Davide\AppData\Local\Programs\Python\Python310\lib\json\encoder.py", line 439, in _iterencode
    yield from _iterencode(o, _current_indent_level)
  File "C:\Users\Davide\AppData\Local\Programs\Python\Python310\lib\json\encoder.py", line 429, in _iterencode
    yield from _iterencode_list(o, _current_indent_level)
  File "C:\Users\Davide\AppData\Local\Programs\Python\Python310\lib\json\encoder.py", line 325, in _iterencode_list
    yield from chunks
  File "C:\Users\Davide\AppData\Local\Programs\Python\Python310\lib\json\encoder.py", line 438, in _iterencode
    o = _default(o)
  File "C:\Users\Davide\Documents\Proyectos Python\aquanode\env\lib\site-packages\rest_framework\utils\encoders.py", line 52, in default
    return obj.decode()
UnicodeDecodeError: 'utf-8' codec can't decode byte 0xbf in position 38: invalid start byte
"GET /api/diagnosis/notifications/ HTTP/1.1" 500 274112
Internal Server Error: /api/diagnosis/notifications/
Traceback (most recent call last):
  File "C:\Users\Davide\Documents\Proyectos Python\aquanode\env\lib\site-packages\django\core\handlers\exception.py", line 55, in inner
    response = get_response(request)
  File "C:\Users\Davide\Documents\Proyectos Python\aquanode\env\lib\site-packages\django\core\handlers\base.py", line 220, in _get_response
    response = response.render()
  File "C:\Users\Davide\Documents\Proyectos Python\aquanode\env\lib\site-packages\django\template\response.py", line 114, in render
    self.content = self.rendered_content
  File "C:\Users\Davide\Documents\Proyectos Python\aquanode\env\lib\site-packages\rest_framework\response.py", line 74, in rendered_content
    ret = renderer.render(self.data, accepted_media_type, context)
  File "C:\Users\Davide\Documents\Proyectos Python\aquanode\env\lib\site-packages\rest_framework\renderers.py", line 727, in render
    context = self.get_context(data, accepted_media_type, renderer_context)
  File "C:\Users\Davide\Documents\Proyectos Python\aquanode\env\lib\site-packages\rest_framework\renderers.py", line 683, in get_context
    'content': self.get_content(renderer, data, accepted_media_type, renderer_context),
  File "C:\Users\Davide\Documents\Proyectos Python\aquanode\env\lib\site-packages\rest_framework\renderers.py", line 413, in get_content
    content = renderer.render(data, accepted_media_type, renderer_context)
  File "C:\Users\Davide\Documents\Proyectos Python\aquanode\env\lib\site-packages\rest_framework\renderers.py", line 100, in render
    ret = json.dumps(
  File "C:\Users\Davide\Documents\Proyectos Python\aquanode\env\lib\site-packages\rest_framework\utils\json.py", line 25, in dumps
    return json.dumps(*args, **kwargs)
  File "C:\Users\Davide\AppData\Local\Programs\Python\Python310\lib\json\__init__.py", line 238, in dumps
    **kw).encode(obj)
  File "C:\Users\Davide\AppData\Local\Programs\Python\Python310\lib\json\encoder.py", line 201, in encode
    chunks = list(chunks)
  File "C:\Users\Davide\AppData\Local\Programs\Python\Python310\lib\json\encoder.py", line 429, in _iterencode
    yield from _iterencode_list(o, _current_indent_level)
  File "C:\Users\Davide\AppData\Local\Programs\Python\Python310\lib\json\encoder.py", line 325, in _iterencode_list
    yield from chunks
  File "C:\Users\Davide\AppData\Local\Programs\Python\Python310\lib\json\encoder.py", line 405, in _iterencode_dict
    yield from chunks
  File "C:\Users\Davide\AppData\Local\Programs\Python\Python310\lib\json\encoder.py", line 439, in _iterencode
    yield from _iterencode(o, _current_indent_level)
  File "C:\Users\Davide\AppData\Local\Programs\Python\Python310\lib\json\encoder.py", line 429, in _iterencode
    yield from _iterencode_list(o, _current_indent_level)
  File "C:\Users\Davide\AppData\Local\Programs\Python\Python310\lib\json\encoder.py", line 325, in _iterencode_list
    yield from chunks
  File "C:\Users\Davide\AppData\Local\Programs\Python\Python310\lib\json\encoder.py", line 438, in _iterencode
    o = _default(o)
  File "C:\Users\Davide\Documents\Proyectos Python\aquanode\env\lib\site-packages\rest_framework\utils\encoders.py", line 52, in default
    return obj.decode()
UnicodeDecodeError: 'utf-8' codec can't decode byte 0xbf in position 38: invalid start byte
"GET /api/diagnosis/notifications/ HTTP/1.1" 500 273895
